Workbook
Name NativeTimeline_Invoice_Date: #N/A
Name Slicer_Region: #N/A

Sheet Sheet1

Sheet Data
B2: Retailer Dataset
B4: Retailer | C4: Retailer ID | D4: Invoice Date | E4: Region | F4: State | G4: City | H4: Beverage Brand | I4: Price per Unit | J4: Units Sold | K4: Total Sales | L4: Operating Profit | M4: Operating Margin
B5: BevCo | C5: 1185732 | D5: 44562 | E5: Northeast | F5: New York | G5: New York | H5: Coca-Cola | I5: 0.5 | J5: 12000 | K5: 6000 | L5: 3000 | M5: 0.5
B6: BevCo | C6: 1185732 | D6: 44563 | E6: Northeast | F6: New York | G6: New York | H6: Diet Coke | I6: 0.5 | J6: 10000 | K6: 5000 | L6: 1500 | M6: 0.3
B7: BevCo | C7: 1185732 | D7: 44564 | E7: Northeast | F7: New York | G7: New York | H7: Sprite | I7: 0.4 | J7: 10000 | K7: 4000 | L7: 1400 | M7: 0.35
B8: BevCo | C8: 1185732 | D8: 44565 | E8: Northeast | F8: New York | G8: New York | H8: Fanta | I8: 0.45 | J8: 8500 | K8: 3825 | L8: 1338.75 | M8: 0.35
B9: BevCo | C9: 1185732 | D9: 44566 | E9: Northeast | F9: New York | G9: New York | H9: Powerade | I9: 0.6 | J9: 9000 | K9: 5400 | L9: 1620 | M9: 0.3
B10: BevCo | C10: 1185732 | D10: 44567 | E10: Northeast | F10: New York | G10: New York | H10: Dasani Water | I10: 0.5 | J10: 10000 | K10: 5000 | L10: 1250 | M10: 0.25
B11: BevCo | C11: 1185732 | D11: 44568 | E11: Northeast | F11: New York | G11: New York | H11: Coca-Cola | I11: 0.5 | J11: 12500 | K11: 6250 | L11: 3125 | M11: 0.5
B12: BevCo | C12: 1185732 | D12: 44569 | E12: Northeast | F12: New York | G12: New York | H12: Diet Coke | I12: 0.5 | J12: 9000 | K12: 4500 | L12: 1350 | M12: 0.3
B13: BevCo | C13: 1185732 | D13: 44582 | E13: Northeast | F13: New York | G13: New York | H13: Sprite | I13: 0.4 | J13: 9500 | K13: 3800 | L13: 1330 | M13: 0.35
B14: BevCo | C14: 1185732 | D14: 44583 | E14: Northeast | F14: New York | G14: New York | H14: Fanta | I14: 0.45 | J14: 8250 | K14: 3712.5 | L14: 1299.375 | M14: 0.35
B15: BevCo | C15: 1185732 | D15: 44584 | E15: Northeast | F15: New York | G15: New York | H15: Powerade | I15: 0.6 | J15: 9000 | K15: 5400 | L15: 1620 | M15: 0.3
B16: BevCo | C16: 1185732 | D16: 44585 | E16: Northeast | F16: New York | G16: New York | H16: Dasani Water | I16: 0.5 | J16: 10000 | K16: 5000 | L16: 1250 | M16: 0.25
... B9652: BevCo | C9652: 1185732 | D9652: 44979 | E9652: Northeast | F9652: New Hampshire | G9652: Manchester | H9652: Sprite | I9652: 0.29 | J9652: 830 | K9652: 240.7 | L9652: 64.989 | M9652: 0.27
C9653: =SUM(C5:C9652) -> 11325302133 | I9653: =SUM(I5:I9652) -> 4362.5 | J9653: =SUM(J5:J9652) -> 24788610 | K9653: =SUM(K5:K9652) -> 12016665 | L9653: =SUM(L5:L9652) -> 4722496.8 | M9653: =SUM(M5:M9652) -> 4081.02

Sheet Analyze
A1: ANALYSIS GUIDE
B3: KPI
B4: 1. TOTAL SALES
B5: 2. DISPLAY AVERAGE OPERATING PROFIT
B6: 3. AVERAGE OPERTATING PROFIT
B7: 4. TOTAL NUMBER OF SOLD
B9: OTHER INFO:
B10: 1. SALES PER RETAILER
B11: 2. SALES PER BEVERAGES
B12: 3. CREATE CHART VISUALS FOR THE SALES ( RETAILER AND BEVERAGES)
B14: Sum of Total Sales
B15: 1667443.4
B18: Average of Operating Profit
B19: 366.45007
B22: Average of Operating Margin
B23: 0.43527244
B25: Count of Units Sold
B26: 1872
B29: SALES PER RETAILER
B30: Row Labels | C30: Count of Units Sold | D30: Sum of Total Sales
B31: BevCo | C31: 840 | D31: 588876.9
B32: FizzyCo | C32: 286 | D32: 321961.6
B33: West Soda | C33: 366 | D33: 276623.6
B34: Target | C34: 244 | D34: 273136.5
B35: Amazon | C35: 136 | D35: 206844.8
B36: Grand Total | C36: 1872 | D36: 1667443.4
B40: SALES COMPARISON PER BRAND (2022-2023)
B41: Sum of Total Sales | C41: Column Labels
B42: Row Labels | C42: 2022 | D42: 2023 | E42: Grand Total
B43: Coca-Cola | C43: 30454.6 | D43: 440281.4 | E43: 470736
B44: Dasani Water | C44: 18117.5 | D44: 327183.3 | E44: 345300.8
B45: Diet Coke | C45: 14351.2 | D45: 247577.7 | E45: 261928.9
B46: Fanta | C46: 7460.4 | D46: 159893.9 | E46: 167354.3
B47: Powerade | C47: 9122.9 | D47: 213255.7 | E47: 222378.6
B48: Sprite | C48: 10885.2 | D48: 188859.6 | E48: 199744.8
B49: Grand Total | C49: 90391.8 | D49: 1577051.6 | E49: 1667443.4
B51: SALES COMPARISON PER RETAILER (2022-2023)
B52: Sum of Total Sales | C52: Column Labels
B53: Row Labels | D53: 2023 | E53: Grand Total
B54: BevCo | C54: 81141.5 | D54: 507735.4 | E54: 588876.9
...

Sheet Dashboard
C12: Brand | D12: Sales 2022 | E12: Sales 2023 | F12: Variance | H12: Brand | I12: Sales 2022 | J12: Sales 2023 | K12: Variance
C13: =Analyze!B43 -> Coca-Cola | D13: =Analyze!C43 -> 30454.6 | E13: =Analyze!D43 -> 440281.4 | F13: =E13-D13 -> 409826.8 | H13: =Analyze!B54 -> BevCo | I13: =Analyze!C54 -> 81141.5 | J13: =Analyze!D54 -> 507735.4 | K13: =J13-I13 -> 426593.9
C14: =Analyze!B44 -> Dasani Water | D14: =Analyze!C44 -> 18117.5 | E14: =Analyze!D44 -> 327183.3 | F14: =E14-D14 -> 309065.8 | H14: =Analyze!B55 -> FizzyCo | I14: =Analyze!C55 -> 0 | J14: =Analyze!D55 -> 321961.6 | K14: =J14-I14 -> 321961.6
C15: =Analyze!B45 -> Diet Coke | D15: =Analyze!C45 -> 14351.2 | E15: =Analyze!D45 -> 247577.7 | F15: =E15-D15 -> 233226.5 | H15: =Analyze!B56 -> West Soda | I15: =Analyze!C56 -> 0 | J15: =Analyze!D56 -> 276623.6 | K15: =J15-I15 -> 276623.6
C16: =Analyze!B46 -> Fanta | D16: =Analyze!C46 -> 7460.4 | E16: =Analyze!D46 -> 159893.9 | F16: =E16-D16 -> 152433.5 | H16: =Analyze!B57 -> Target | I16: =Analyze!C57 -> 9250.3 | J16: =Analyze!D57 -> 263886.2 | K16: =J16-I16 -> 254635.9
C17: =Analyze!B47 -> Powerade | D17: =Analyze!C47 -> 9122.9 | E17: =Analyze!D47 -> 213255.7 | F17: =E17-D17 -> 204132.8 | H17: =Analyze!B58 -> Amazon | I17: =Analyze!C58 -> 0 | J17: =Analyze!D58 -> 206844.8 | K17: =J17-I17 -> 206844.8
C18: =Analyze!B48 -> Sprite | D18: =Analyze!C48 -> 10885.2 | E18: =Analyze!D48 -> 188859.6 | F18: =E18-D18 -> 177974.4 | H18: =Analyze!B59 -> Grand Total | I18: =Analyze!C59 -> 90391.8 | J18: =Analyze!D59 -> 1577051.6 | K18: =J18-I18 -> 1486659.8
C19: =Analyze!B49 -> Grand Total | D19: =Analyze!C49 -> 90391.8 | E19: =Analyze!D49 -> 1577051.6 | F19: =E19-D19 -> 1486659.8 | H19: =Analyze!B60 -> 0 | I19: =Analyze!C60 -> 0 | J19: =Analyze!D60 -> 0 | K19: =J19-I19 -> 0
